<?xml version='1.0'?>
<sdf version="1.5">
<model name="bowser2">
  <pose>0 0 .5 0 0 0</pose>
<!--   <xacro:property name="x" value=".9"/>
  <xacro:property name="y" value=".6"/>
  <xacro:property name="z" value=".3"/>
  <xacro:property name="mass" value="100"/> -->
  <static>false</static>
  <link name="base_link">
    <inertial>
      <mass>10</mass>
      <inertia> <!-- inertias are tricky to compute -->
        <!-- http://gazebosim.org/tutorials?tut=inertia&cat=build_robot -->
        <!-- <ixx>4.6314</ixx>         for a box: ixx = 0.083 * mass * (y*y + z*z) -->
        <ixx>.3735</ixx>
        <ixy>0.0</ixy>            <!-- for a box: ixy = 0 -->
        <ixz>0.0</ixz>            <!-- for a box: ixz = 0 -->
        <!-- <iyy>9.2628</iyy>         for a box: iyy = 0.083 * mass * (x*x + z*z) -->
        <iyy>.747</iyy>
        <iyz>0.0</iyz>            <!-- for a box: iyz = 0 -->
        <izz>.9711</izz>
        <!-- <izz>12.04164</izz>       for a box: izz = 0.083 * mass * (x*x + y*y) -->
      </inertia>
    </inertial>
    <collision name="collision">
      <geometry>
        <box>
          <size>.9 .6 .3</size>
        </box>
      </geometry>
    </collision>
    <visual name="visual">
      <geometry>
        <box>
          <size>.9 .6 .3</size>
        </box>
      </geometry>
    </visual>

    <collision name='caster_collision'>
      <pose>.35 0 -0.15 0 0 0</pose>
      <geometry>
          <sphere>
          <radius>.075</radius>
        </sphere>
      </geometry>
      <surface>
        <friction>
          <ode>
            <mu>0</mu>
            <mu2>0</mu2>
            <slip1>1.0</slip1>
            <slip2>1.0</slip2>
          </ode>
        </friction>
      </surface>
    </collision>  
    <visual name='caster_visual'>
      <pose>.35 0 -.15 0 0 0</pose>
      <geometry>
        <sphere>
          <radius>.075</radius>
        </sphere>
      </geometry>
    </visual>

  </link>

  <link name="front_left_wheel">
    <pose>-0.3 -.37 -0.05 0 0 0</pose>
    <inertial>
      <mass>2.6357</mass>
      <pose>0 0 0 0 0 0</pose>
      <inertia>
        <ixx>0.0246688</ixx>
        <ixy>0</ixy>
        <ixz>0</ixz>
        <iyy>0.0246688</iyy>
        <iyz>0</iyz>
        <izz>0.0441058</izz>
      </inertia>
    </inertial>
    <collision name="front_left_wheel_collision">
      <pose>0 0 0 -1.5707 0 0</pose>
      <geometry>
        <cylinder>
          <radius>0.17775</radius>
          <length>0.1143</length>
        </cylinder>
      </geometry>
      <surface>
        <friction>
          <ode>
            <mu>100000.0</mu>
            <mu2>100000.0</mu2>
            <slip1>0.0</slip1>
            <slip2>0.0</slip2>
          </ode>
        </friction>
      </surface>
    </collision>
    <visual name="front_left_wheel">
      <pose>0 0 0 -3.14159 0 0</pose>
      <geometry>
        <mesh>
          <uri>model://husky/meshes/wheel.stl</uri>
        </mesh>
      </geometry>
      <material>
        <script>
          <name>Gazebo/Grey</name>
        </script>
      </material>
    </visual>
  </link>
  <joint name="front_left_joint" type="revolute">
    <parent>base_link</parent>
    <child>front_left_wheel</child>
    <axis>
      <xyz>0 1 0</xyz>
      <use_parent_model_frame>true</use_parent_model_frame>
    </axis>
    <physics>
      <ode>
        <limit>
          <cfm>0.000000</cfm>
          <erp>0.900000</erp>
        </limit>
      </ode>
    </physics>
  </joint>

  <link name="front_right_wheel">
    <pose>-0.3 .37 -0.05 0 0 0</pose>
    <inertial>
      <mass>2.6357</mass>
      <pose>0 0 0 0 0 0</pose>
      <inertia>
        <ixx>0.0246688</ixx>
        <ixy>0</ixy>
        <ixz>0</ixz>
        <iyy>0.0246688</iyy>
        <iyz>0</iyz>
        <izz>0.0441058</izz>
      </inertia>
    </inertial>
    <collision name="front_right_wheel_collision">
      <pose>0 0 0 -1.5707 0 0</pose>
      <geometry>
        <cylinder>
          <radius>0.17775</radius>
          <length>0.1143</length>
        </cylinder>
      </geometry>
      <surface>
        <friction>
          <ode>
            <mu>100000.0</mu>
            <mu2>100000.0</mu2>
            <slip1>0.0</slip1>
            <slip2>0.0</slip2>
          </ode>
        </friction>
      </surface>
    </collision>
    <visual name="front_right_wheel">
      <pose>0 0 0 -3.14159 0 0</pose>
      <geometry>
        <mesh>
          <uri>model://husky/meshes/wheel.stl</uri>
        </mesh>
      </geometry>
      <material>
        <script>
          <name>Gazebo/Grey</name>
        </script>
      </material>
    </visual>
  </link>
  <joint name="front_right_joint" type="revolute">
    <parent>base_link</parent>
    <child>front_right_wheel</child>
    <axis>
      <xyz>0 1 0</xyz>
      <use_parent_model_frame>true</use_parent_model_frame>
    </axis>
    <physics>
      <ode>
        <limit>
          <cfm>0.000000</cfm>
          <erp>0.900000</erp>
        </limit>
      </ode>
    </physics>
  </joint>

  <include>
    <uri>model://bowser_hdl32</uri>
    <pose> -.35 0 .2 0 0 3.14159 </pose>
  </include>	
  <joint name="hdl32_joint" type="fixed">
  	<parent>base_link</parent>
  	<child>bowser_hdl32::hdl32_base</child>
  </joint>	

  <plugin filename="libgazebo_ros_diff_drive.so" name="diff_drive_controller">
    <robotNamespace></robotNamespace>
  	<alwaysOn>true</alwaysOn>
		<updateRate>100</updateRate>

		<leftJoint>front_left_joint</leftJoint>
		<rightJoint>front_right_joint</rightJoint>
		<wheelSeparation>0.74</wheelSeparation>
    <wheelDiameter>0.3555</wheelDiameter>
    <torque>20</torque>

    <commandTopic>/cmd_vel</commandTopic>
    <odometryTopic>/odom</odometryTopic>
    <odometryFrame>/odom</odometryFrame>
    <robotBaseFrame>base_link</robotBaseFrame>
  </plugin>

  <plugin name="imu_plugin" filename="libgazebo_ros_imu.so">
    <robotNamespace></robotNamespace>
    <alwaysOn>true</alwaysOn>       
    <bodyName>base_link</bodyName>
    <topicName>/bowser2/imu</topicName>
    <serviceName>imu_service</serviceName>
    <gaussianNoise>0.0</gaussianNoise>
    <updateRate>10.0</updateRate> 
  </plugin>

  <include>
    <uri>model://bowser_depthcam</uri>
    <pose> 0 0 .7 0 0 3.14159</pose>
  </include>
  <joint name="depthcam_joint" type="fixed">
    <parent>base_link</parent>
    <child>bowser_depthcam::dc_link</child>
  </joint>    

<!--   <plugin name="imu_cam_plugin" filename="libgazebo_ros_imu.so">
    <robotNamespace></robotNamespace>
    <alwaysOn>true</alwaysOn>       
    <bodyName>bowser_depthcam::dc_link</bodyName>
    <topicName>/bowser2/imu_cam</topicName>
    <serviceName>imu_cam_service</serviceName>
    <gaussianNoise>0.0</gaussianNoise>
    <updateRate>10.0</updateRate> 
  </plugin>
 -->
<!--   <include>
    <uri>model://bowser_left_camera</uri>
    <pose>0 .3 .1 0 0 1.5708</pose>
  </include>
  <joint name="left_camera_joint" type="fixed">
    <parent>base_link</parent>
    <child>bowser_left_camera::lc_link</child>
  </joint>

  <include>
    <uri>model://bowser_right_camera</uri>
    <pose>0 -.3 .1 0 0 -1.5708</pose>
  </include>
  <joint name="right_camera_joint" type="fixed">
    <parent>base_link</parent>
    <child>bowser_right_camera::rc_link</child>
  </joint> -->


<!-- Hector gazebo plugins not supported for Noetic. Yet. Needs to be built from source. -->
  <plugin name="gps_controller" filename="libhector_gazebo_ros_gps.so">
    <alwayson>true</alwayson>
    <updaterate>1.0</updaterate>
    <bodyname>base_link</bodyname>
    <topicname>/bowser2/fix</topicname>
    <velocitytopicname>/bowser2/fix_velocity</velocitytopicname>
    <drift>5.0 5.0 5.0</drift>
    <gaussiannoise>0.1 0.1 0.1</gaussiannoise>
    <velocitydrift>0 0 0</velocitydrift>
    <velocitygaussiannoise>0.1 0.1 0.1</velocitygaussiannoise>
  </plugin>

  </model>
</sdf>
